Workbook

Sheet Карточка
J3: Приложение № 22
J4: к Инструкции (пп. 31 – 34)
L5: Форма № 10
A6: КАРТОЧКА
A7: гражданина, подлежащего воинскому учету в
A8: <Полное наименование>
A9: (наименование организации)
A10: Сверка с документами воинского учета | C10: =K100 -> <Инициалы имени, отчества ответственного за ВУ> <Фамилия ответственного за ВУ> | G10: Сверка с военным комиссариатом | H10: =K100 -> <Инициалы имени, отчества ответственного за ВУ> <Фамилия ответственного за ВУ>
C12: (дата, подпись, инициал имени, фамилия лица, проводившего сверку) | H12: (дата, подпись, инициал имени, фамилия лица, проводившего сверку, или номер исходящего письма со списком для сверки)
A13: I. Общие сведения
A15: 1. Фамилия | D15: <Фамилия>
A17: Имя | D17: <Имя>
A19: Отчество (при наличии) | D19: <Отчество>
A21: 2. Дата рождения | D21: <Дата рождения>
A23: 3. Место рождения | D23: <Место рождения>
A25: 4. Образование | D25: <Вид образования>
D26: (уровень образования)
A27: <Учебное заведение> | F27: <Квалификация> | J27: <Специальность>
F28: (квалификация) | J28: (специальность, направление подготовки)
F29: <Серия квалификационного документа> <Номер квалификационного документа> | J29: <Период обучения по>
A30: (наименование образовательной организации) | E30: (серия и номер диплома, свидетельства) | J30: (год окончания)
A31: 5. Профессия
D32: (основная) | J32: (дополнительная)
A33: 6. Семейное положение | D33: <Семейное положение>
A35: 7. Состав семьи | D35: <Степень родства> | F35: <Фамилия родственника> <Имя родственника> <Отчество родственника> <Дата рождения родственника>
D36: (степень родства) | F36: (фамилия, имя, отчество (при наличии), год рождения)
D37: <Степень родства2> | F37: <Фамилия родственника2> <Имя родственника2> <Отчество родственника2> <Дата рождения родственника2>
D38: (степень родства) | F38: (фамилия, имя, отчество (при наличии), год рождения)
D39: <Степень родства3> | F39: <Фамилия родственника3> <Имя родственника3> <Отчество родственника3> <Дата рождения родственника3>
D40: (степень родства) | F40: (фамилия, имя, отчество (при наличии), год рождения)
D41: <Степень родства4> | F41: <Фамилия родственника4> <Имя родственника4> <Отчество родственника4> <Дата рождения родственника4>
D42: (степень родства) | F42: (фамилия, имя, отчество (при наличии), год рождения)
A43: 8. Знание иностранных языков
D45: (наименование) | F45: (степень знания) | J45: (наименование) | L45: (степень знания)
A46: 9. Паспорт | D46: <Серия документа, удостоверяющего личность> | F46: <Номер документа, удостоверяющего личность> | J46: <Дата выдачи документа, удостоверяющего личность> г.
D47: (серия) | F47: (номер) | J47: (дата выдачи)
A48: <Орган, выдавший документ, удостоверяющего личность> | J48: код подразделения | L48: <Код подразделения>
A49: (кем выдан)
A50: 10. Водительское удостоверение
D52: (серия) | F52: (номер) | I52: (категории ТС) | L52: (дата выдачи)
...

Sheet Карточка (2)
J3: Приложение № 22
J4: к Инструкции (пп. 31 – 34)
L5: Форма № 10
A6: КАРТОЧКА
A7: гражданина, подлежащего воинскому учету в
A8: Общество с ограниченной ответственностью "СЫТОСТЬ"
A9: (наименование организации)
A10: Сверка с документами воинского учета | G10: Сверка с военным комиссариатом
C12: (дата, подпись, инициал имени, фамилия лица, проводившего сверку) | H12: (дата, подпись, инициал имени, фамилия лица, проводившего сверку, или номер исходящего письма со списком для сверки)
A13: I. Общие сведения
A15: 1. Фамилия | D15: <Фамилия>
A17: Имя | D17: <Имя>
A19: Отчество (при наличии) | D19: <Отчество>
A21: 2. Дата рождения | D21: <Дата рождения>
A23: 3. Место рождения | D23: <Место рождения>
A25: 4. Образование | D25: <Вид образования>
D26: (уровень образования)
A27: <Учебное заведение> | F27: <Квалификация> | J27: <Специальность>
F28: (квалификация) | J28: (специальность, направление подготовки)
F29: <Серия квалификационного документа> <Номер квалификационного документа> | J29: <Период обучения по>
A30: (наименование образовательной организации) | E30: (серия и номер диплома, свидетельства) | J30: (год окончания)
A31: 5. Профессия
D32: (основная) | J32: (дополнительная)
A33: 6. Семейное положение
A35: 7. Состав семьи
D36: (степень родства) | F36: (фамилия, имя, отчество (при наличии), год рождения)
D38: (степень родства) | F38: (фамилия, имя, отчество (при наличии), год рождения)
D40: (степень родства) | F40: (фамилия, имя, отчество (при наличии), год рождения)
D42: (степень родства) | F42: (фамилия, имя, отчество (при наличии), год рождения)
A43: 8. Знание иностранных языков
D45: (наименование) | F45: (степень знания) | J45: (наименование) | L45: (степень знания)
A46: 9. Паспорт
D47: (серия) | F47: (номер) | J47: (дата выдачи)
J48: код подразделения
A49: (кем выдан)
A50: 10. Водительское удостоверение
D52: (серия) | F52: (номер) | I52: (категории ТС) | L52: (дата выдачи)
A54: 11. Адрес места жительства (места пребывания)
D55: (в соответствии с регистрацией) | L55: (дата регистрации)
D57: (фактический) | K57: (дата начала проживания)
...

Sheet Сведения
A1: <Краткое наименование> | G1: Военному комиссару (руководителю)
A2: ИНН/КПП | B2: <ИНН организации>/<КПП организации> | M2: (наименование
A3: ОГРН(-ИП) <ОГРН организации> | G3: =Карточка!G95 -> <Военкомат>
G5: военного комиссариата, органа местного самоуправления)
G6: <Адрес военкомата>
A9: СВЕДЕНИЯ о гражданине, подлежащем воинскому учету, при принятии (поступлении) его на работу (в образовательную организацию) или увольнении (отчислении) его с работы (из образовательной организации)
A16: Сообщаю, что гражданин | D16: =Карточка!D15 -> <Фамилия> | H16: =Карточка!D17 -> <Имя> | L16: =Карточка!D19 -> <Отчество>
H17: (ф.и.о.)
A18: подлежащий воинскому учету, воинское звание | J18: =Карточка!D67 -> <Воинское звание>
A20: дата рождения | C20: =Карточка!D21 -> <Дата рождения> | F20: , серия и номер паспорта | L20: =Карточка!D46 -> <Серия документа, удостоверяющего личность> | N20: =Карточка!F46 -> <Номер документа, удостоверяющего личность>
A22: страховой номер индивидуального лицевого счета | J22: <СНИЛС>
A23: проживающий адрес регистрации: | D23: =Карточка!D54 -> <Адрес по прописке>
A24: фактический адрес: | D24: =Карточка!D56 -> <Адрес места проживания>
A26: принят (поступил), | D26: уволен с работы (отчислен из образовательной организации)
B27: (ненужное зачеркнуть)
A28: =Карточка!A8 -> <Полное наименование>
A29: (полное наименование организации, образовательной организации,
A30: Юридический адрес: | D30: <Юридический адрес>
A31: Фактический адрес: | D31: <Фактический адрес>
D32: место нахождения, фактический адрес организации (образовательной организации)
A33: на должность | D33: =Карточка!C95 -> <Должность работника>
A34: на основании приказа (трудового договора) № | I34: =Карточка!A95 -> <Приказ №> | L34: от | M34: =Карточка!B95 -> <Дата приказа о приеме>
A36: Руководитель организации (образовательной организации)
A38: <Должность руководителя> | M38: <Инициалы имени, отчества руководителя> <Фамилия руководителя>
A39: (должность) | H39: (подпись) | M39: (ф.и.о.)
B41: М.П. (при наличии)
A43: Ответственный за военно-учетную работу
A45: =Карточка!D100 -> <Должность ответственного за ВУ> | M45: =Карточка!K100 -> <Инициалы имени, отчества ответственного за ВУ> <Фамилия ответственного за ВУ>
A46: (должность) | H46: (подпись) | M46: (ф.и.о.)

Sheet Сверка
V1: Приложение № 23
U2: к Инструкции (п. 36)
D3: =Сведения!A1 -> <Краткое наименование> | N3: Военному комиссару
D4: ИНН/КПП | F4: =Сведения!B2 -> <ИНН организации>/<КПП организации> | N4: =Карточка!G95 -> <Военкомат>
D5: =Сведения!A3 -> ОГРН(-ИП) <ОГРН организации>
N6: =Сведения!D30 -> <Юридический адрес>
B9: Список граждан, пребывающих в запасе, работающих в
B10: =Карточка!A8 -> <Полное наименование>
G11: (наименование организации)
G12: для сверки учетных сведений о воинском учете, содержащихся в личных карточках
B13: Адрес организации | H13: =Сведения!D31 -> <Фактический адрес>
B14: Ответственный за военно-учетную работу | K14: =Карточка!D100 -> <Должность ответственного за ВУ> | P14: 8-926-641-37-58 | T14: =Карточка!K100 -> <Инициалы имени, отчества ответственного за ВУ> <Фамилия ответственного за ВУ>
J15: (должность) | T15: (инициал имени, фамилия)
B16: № п/п | C16: Фамилия, имя, отчество (при наличии) | F16: Воинское звание | H16: Категория запаса | I16: Состав (профиль) | K16: Полное кодовое обозначение ВУС | L16: Категория годности к военной службе | N16: Состоит на воинском учете: общий (номер команды, партии), специальный | O16: Дата и место рождения | Q16: Образование | R16: Место жительства (место пребывания) | T16: Семейное положение | V16: Структурное подразделение организации, должность (профессия)
B17: 1 | C17: 2 | F17: 3 | H17: 4 | I17: 5 | K17: 6 | L17: 7 | N17: 8 | O17: 9 | Q17: 10 | R17: 11 | T17: 12 | V17: 13
B18: 1 | C18: =Карточка!D15 -> <Фамилия> | F18: =Карточка!D67 -> <Воинское звание> | H18: =Карточка!D63 -> <Категория запаса> | I18: =Карточка!D70 -> <Состав (профиль)> | K18: =Карточка!D74 -> <ВУС> | L18: =Карточка!D77 -> <Годность к воинской службе> | N18: общий | O18: =Карточка!D21 -> <Дата рождения> | Q18: =Карточка!D25 -> <Вид образования> | R18: =Карточка!D54 -> <Адрес по прописке> | T18: =Карточка!D33 -> <Семейное положение> | V18: <Подразделение>
C19: =Карточка!D17 -> <Имя> | O19: =Карточка!D23 -> <Место рождения> | T19: =Карточка!D35 -> <Степень родства>
C20: =Карточка!D19 -> <Отчество> | T20: =Карточка!F35 -> <Фамилия родственника> <Имя родственника> <Отчество родственника> <Дата рождения родственника>
Q22: =Карточка!A27 -> <Учебное заведение> | V22: =Карточка!C95 -> <Должность работника>
T23: =Карточка!D37 -> <Степень родства2>
T24: =Карточка!F37 -> <Фамилия родственника2> <Имя родственника2> <Отчество родственника2> <Дата рождения родственника2>
R26: (Фактический)
R27: =Карточка!D56 -> <Адрес места проживания> | T27: =Карточка!D39 -> <Степень родства3>
Q28: =Карточка!F27 -> <Квалификация> | T28: =Карточка!F39 -> <Фамилия родственника3> <Имя родственника3> <Отчество родственника3> <Дата рождения родственника3>
Q29: =Карточка!J27 -> <Специальность>
T31: =Карточка!D41 -> <Степень родства4>
T32: =Карточка!F41 -> <Фамилия родственника4> <Имя родственника4> <Отчество родственника4> <Дата рождения родственника4>
Q34: =Карточка!J29 -> <Период обучения по> | R34: =Карточка!J58 -> <Мобильный телефон>
B36: Руководитель организации | S36: =Сведения!M38 -> <Инициалы имени, отчества руководителя> <Фамилия руководителя>
I37: (подпись, инициал имени, фамилия)

Sheet Сведения прил. 10
P1: Приложение N 10 к Методическим рекомендациям (п. 29)
C2: =Сведения!A1 -> <Краткое наименование> | M2: Военному комиссару
C3: ИНН/КПП | E3: =Сведения!B2 -> <ИНН организации>/<КПП организации> | M3: =Карточка!G95 -> <Военкомат>
C4: =Сведения!A3 -> ОГРН(-ИП) <ОГРН организации>
M5: =Сведения!G6 -> <Адрес военкомата>
A7: Список о гражданах, состоящих на воинском учете, а также о гражданах, не состоящих, но обязанных состоять на воинском учете
A8: =Карточка!A8 -> <Полное наименование>
F9: (наименование организации)
A11: Адрес организации | G11: =Сведения!D31 -> <Фактический адрес>
A12: Ответственный за военно-учетную работу | J12: =Карточка!D100 -> <Должность ответственного за ВУ> | O12: =Сверка!P14 -> 8-926-641-37-58 | S12: =Карточка!K100 -> <Инициалы имени, отчества ответственного за ВУ> <Фамилия ответственного за ВУ>
I13: (должность) | S13: (инициал имени, фамилия)
A14: № п/п | B14: Фамилия, имя, отчество (при наличии) | E14: Воинское звание | G14: Категория запаса | H14: Состав (профиль) | J14: Полное кодовое обозначение ВУС | K14: Категория годности к военной службе | M14: Состоит на воинском учете: общий (номер команды, партии), специальный | N14: Дата и место рождения | P14: Образование | Q14: Место жительства (место пребывания) | S14: Семейное положение | U14: Структурное подразделение организации, должность (профессия)
A15: 1 | B15: 2 | E15: 3 | G15: 4 | H15: 5 | J15: 6 | K15: 7 | M15: 8 | N15: 9 | P15: 10 | Q15: 11 | S15: 12 | U15: 13
A16: 1 | B16: =Карточка!D15 -> <Фамилия> | E16: =Карточка!D67 -> <Воинское звание> | G16: =Карточка!D63 -> <Категория запаса> | H16: =Карточка!D70 -> <Состав (профиль)> | J16: =Карточка!D74 -> <ВУС> | K16: =Карточка!D77 -> <Годность к воинской службе> | M16: Не состоит, но должен | N16: =Карточка!D21 -> <Дата рождения> | P16: =Карточка!D25 -> <Вид образования> | Q16: =Карточка!D54 -> <Адрес по прописке> | S16: =Карточка!D33 -> <Семейное положение> | U16: =Сверка!V18 -> <Подразделение>
B17: =Карточка!D17 -> <Имя> | N17: =Карточка!D23 -> <Место рождения> | S17: =Карточка!D35 -> <Степень родства>
B18: =Карточка!D19 -> <Отчество> | S18: =Карточка!F35 -> <Фамилия родственника> <Имя родственника> <Отчество родственника> <Дата рождения родственника>
P20: =Карточка!A27 -> <Учебное заведение> | U20: =Карточка!C95 -> <Должность работника>
S21: =Карточка!D37 -> <Степень родства2>
S22: =Карточка!F37 -> <Фамилия родственника2> <Имя родственника2> <Отчество родственника2> <Дата рождения родственника2>
Q24: (Фактический)
P25: =Карточка!F27 -> <Квалификация> | Q25: =Карточка!D56 -> <Адрес места проживания> | S25: =Карточка!D39 -> <Степень родства3>
S26: =Карточка!F39 -> <Фамилия родственника3> <Имя родственника3> <Отчество родственника3> <Дата рождения родственника3>
P27: =Карточка!J27 -> <Специальность>
S29: =Карточка!D41 -> <Степень родства4>
S30: =Карточка!F41 -> <Фамилия родственника4> <Имя родственника4> <Отчество родственника4> <Дата рождения родственника4>
P32: =Карточка!J29 -> <Период обучения по> | Q32: =Карточка!J58 -> <Мобильный телефон>
A34: Руководитель организации | R34: =Сведения!M38 -> <Инициалы имени, отчества руководителя> <Фамилия руководителя>
H35: (подпись, инициал имени, фамилия)

Sheet Листок сообщения
A1: КОРЕШОК ЛИСТКА СООБЩЕНИЯ об изменениях сведений о гражданах, состоящих на воинском учете | B1: На основании статьи 10 Федерального закона «О воинской обязанности и военной службе» и статьи 50 Положения о воинском учете, утвержденного постановлением Правительства Российской Федерации от 27 ноября 2006 г. №719 граждане, подлежащие воинскому учету, обязаны сообщить двухнедельный срок в военный комиссариат, в котором они состоят на воинском учете либо в соответствующий орган местного самоуправления, осуществляющий первичный воинский учет об изменении сведений о семейном положении, образовании, состоянии здоровья (получении инвалидности), месте работы или должности, месте жительства или места пребывания в пределах территории, на которой осуществляет свою деятельность военный комиссариат, в котором они состоят на воинском учете.
A2: Фамилия | B2: ЛИСТОК СООБЩЕНИЯ
A3: =Карточка!D15 -> <Фамилия> | B3: об изменениях сведений о гражданах, состоящих на воинском учете
A4: Имя | B4: Фамилия | D4: =Карточка!D15 -> <Фамилия>
A5: =Карточка!D17 -> <Имя> | B5: Имя и отчество | D5: =Карточка!D17 -> <Имя> | H5: =Карточка!D19 -> <Отчество>
A6: Отчество | B6: Год рождения | D6: =Карточка!D21 -> <Дата рождения>
A7: =Карточка!D19 -> <Отчество> | B7: Воинское звание, ВУС | E7: =Карточка!D67 -> <Воинское звание> | I7: =Карточка!D74 -> <ВУС>
A8: Наименование структурного подразделения организации | B8: Образование | D8: =Карточка!D25 -> <Вид образования>
B9: Место работы: | D9: =Карточка!A8 -> <Полное наименование>
A10: =Сверка!V18 -> <Подразделение> | B10: Юридический адрес: | E10: =Сведения!D30 -> <Юридический адрес>
A11: =Карточка!A8 -> <Полное наименование> | B11: Фактический адрес: | E11: =Сведения!D31 -> <Фактический адрес>
B13: Должность | D13: =Карточка!C95 -> <Должность работника>
A14: =Сведения!A1 -> <Краткое наименование> | B14: Состояние здоровья (получение инвалидности) | F14: =Карточка!D77 -> <Годность к воинской службе>
A15: Юридический адрес: | B15: Семейное положение | F15: =Карточка!D33 -> <Семейное положение>
A16: =Сведения!D30 -> <Юридический адрес> | B16: =Карточка!D35 -> <Степень родства> | C16: =Карточка!F35 -> <Фамилия родственника> <Имя родственника> <Отчество родственника> <Дата рождения родственника>
B17: =Карточка!D37 -> <Степень родства2> | C17: =Карточка!F37 -> <Фамилия родственника2> <Имя родственника2> <Отчество родственника2> <Дата рождения родственника2>
B18: =Карточка!D39 -> <Степень родства3> | C18: =Карточка!F39 -> <Фамилия родственника3> <Имя родственника3> <Отчество родственника3> <Дата рождения родственника3>
B19: =Карточка!D41 -> <Степень родства4> | C19: =Карточка!F41 -> <Фамилия родственника4> <Имя родственника4> <Отчество родственника4> <Дата рождения родственника4>
A20: Фактический адрес: | B20: =Карточка!D56 -> <Адрес места проживания>
A21: =Сведения!D31 -> <Фактический адрес>
B22: (фамилия, имя, отчество супруги (а), год рождении детей и их место жительства, для граждан, не состоящих в браке – фамилия, имя, отчество матери (отца) или ближайших родственников и адрес их места жительства)
B23: место жительства (место пребывания) | E23: =Карточка!D56 -> <Адрес места проживания>
A24: Отметка (мастичный штамп) военного комиссариата муниципального образования (муниципальных образований) (органа местного самоуправления, осуществляющего первичный воинский учет) о получении листка сообщения от гражданина
B29: Данные сверил:
B30: Ответственный за ВУР | I30: =Карточка!K100 -> <Инициалы имени, отчества ответственного за ВУ> <Фамилия ответственного за ВУ>
G31: (подпись) | I31: (инициалы имени, фамилия)
B32: Тел.: | C32: =Сверка!P14 -> 8-926-641-37-58
A34: (подпись) | B34: «____» ________________ 20 ___ г.
A35: «____» ___________ 20 ___ г.

Sheet Уведомление 1
A1: =Карточка!A8 -> <Полное наименование>
A2: =Сведения!A1 -> <Краткое наименование>
A3: =Сведения!D30 -> <Юридический адрес>
C4: ИНН/КПП | D4: =Сведения!B2 -> <ИНН организации>/<КПП организации> | G4: =Сведения!A3 -> ОГРН(-ИП) <ОГРН организации>
A6: УВЕДОМЛЕНИЕ
A8: Уважаемый (ая) | D8: =Карточка!D15 -> <Фамилия> | G8: =Карточка!D17 -> <Имя> | J8: =Карточка!D19 -> <Отчество> | M8: !
A10: Согласно ст. 8, 10 Федерального Закона от 28.03.1998 № 53-ФЗ "О воинской обязанности и военной службе" граждане обязаны состоять на воинском учете в военном комиссариате по месту постоянной регистрации.
A11: Вам необходимо обратиться в | F11: =Карточка!G95 -> <Военкомат>
A12: адрес: | B12: =Сведения!G6 -> <Адрес военкомата>
A13: по месту вашей регистрации, оформить постановку на воинский учет и предоставить оформленные документы воинского учета в отдел кадров.
A14: Для посещения военкомата необходимо иметь при себе следующие документы:
A15: 1) скан всех страниц документа воинского учета (военного билета, приписного удостоверения) с действующей отметкой о постановке на учет;
A16: 2) скан свидетельства о временной регистрации (если есть);
A17: 3) заявление (приложение № 3 к постановлению Правительства РФ от 27.11.2006 № 719);
A18: 4) сведения от работодателя (приложение № 2 к постановлению Правительства от 27.11.2006 № 719).
A20: Напоминаем Вам о том, что неявка гражданина, состоящего или обязанного состоять на воинском учете в военном комиссариате, в установленный срок для постановки на воинский учет, снятия с воинского учета и внесения изменений в документы воинского учета при переезде на новое место жительства, влечет за собой привлечение к административной ответственности по ст. 21.5 КоАП Российской Федерации - наложение административного штрафа в размере от 1 000 до 10 000 руб.
A29: С уважением,
A30: Специалист по воинскому учету | J30: =Карточка!K100 -> <Инициалы имени, отчества ответственного за ВУ> <Фамилия ответственного за ВУ>
G31: подпись
A32: Тел. | B32: =Сверка!P14 -> 8-926-641-37-58
A33: Военнообязанный пишет от руки
A34: Уведомление получил, дата, подпись, фамилия и инициалы

Sheet Уведомление 2
A1: =Карточка!A8 -> <Полное наименование>
A2: =Сведения!A1 -> <Краткое наименование>
A3: =Сведения!D30 -> <Юридический адрес>
C4: ИНН/КПП | D4: =Сведения!B2 -> <ИНН организации>/<КПП организации> | G4: =Сведения!A3 -> ОГРН(-ИП) <ОГРН организации>
A6: УВЕДОМЛЕНИЕ
A8: Уважаемый (ая) | D8: =Карточка!D15 -> <Фамилия> | G8: =Карточка!D17 -> <Имя> | J8: =Карточка!D19 -> <Отчество> | M8: !
A9: Согласно ст. 8, 10 Федерального Закона от 28.03.1998 № 53-ФЗ "О воинской обязанности и военной службе" граждане, прибывшие на место пребывания на срок более трех месяцев, обязаны состоять на воинском учете в военном комиссариате по месту пребывания. Воинский учет граждан, прибывших на место пребывания на срок более трех месяцев и не имеющих регистрации по месту пребывания осуществляется военными комиссариатами по месту, указываемому гражданами в заявлении в качестве места их пребывания (учебы), по форме и в порядке, которые устанавливаются Положением о воинском учете. Отсутствие у граждан регистрации по месту пребывания не освобождает их от обязанности состоять на воинском учете и не может служить основанием для отказа в постановке их на воинский учет.
A10: Вам необходимо обратиться в | F10: =Карточка!G95 -> <Военкомат>
A11: адрес: | B11: =Сведения!G6 -> <Адрес военкомата>
A12: по месту вашей регистрации, оформить постановку на воинский учет и предоставить оформленные документы воинского учета в отдел кадров.
A13: Для посещения военкомата необходимо иметь при себе следующие документы:
A14: 1) скан всех страниц документа воинского учета (военного билета, приписного удостоверения) с действующей отметкой о постановке на учет;
A15: 2) скан свидетельства о временной регистрации (если есть);
A16: 3) заявление (приложение № 3 к постановлению Правительства РФ от 27.11.2006 № 719);
A17: 4) сведения от работодателя (приложение №2 к постановлению Правительства от 27.11.2006 № 719).
A18: Напоминаем Вам о том, что неявка гражданина, состоящего или обязанного состоять на воинском учете в военном комиссариате, в установленный срок для постановки на воинский учет, снятия с воинского учета и внесения изменений в документы воинского учета при переезде на новое место жительства, влечет за собой привлечение к административной ответственности по ст. 21.5 КоАП Российской Федерации - наложение административного штрафа в размере от 1 000 до 10 000 руб.
A27: С уважением,
A28: Специалист по воинскому учету | J28: =Карточка!K100 -> <Инициалы имени, отчества ответственного за ВУ> <Фамилия ответственного за ВУ>
G29: подпись
A30: Тел. | B30: =Сверка!P14 -> 8-926-641-37-58
A31: Военнообязанный пишет от руки: Уведомление получил, дата, подпись, фамилия и инициалы

Sheet Направление
F1: Л И Н И Я О Т Р Е З А | H1: Приложение № 3 к Инструкции (п. 6)
A2: КОРЕШОК НАПРАВЛЕНИЯ ДЛЯ ПОСТАНОВКИ | G2: =Карточка!D15 -> <Фамилия>
G3: =Карточка!D17 -> <Имя>
G4: =Карточка!D19 -> <Отчество>
A5: НА ВОИНСКИЙ УЧЕТ № | G5: (фамилия, имя, отчество гражданина)
A6: =Карточка!D15 -> <Фамилия> | G6: Регистрируется по адресу:
A7: (фамилия, имя, отчество гражданина) | G7: =Карточка!D56 -> <Адрес места проживания>
A8: =Карточка!D17 -> <Имя> | C8: =Карточка!D19 -> <Отчество>
A9: Дата рождения | C9: =Карточка!D21 -> <Дата рождения> | G9: НАПРАВЛЕНИЕ ДЛЯ ПОСТАНОВКИ
A10: Паспорт серии | C10: =Карточка!D46 -> <Серия документа, удостоверяющего личность> | D10: № | E10: =Карточка!F46 -> <Номер документа, удостоверяющего личность> | G10: НА ВОИНСКИЙ УЧЕТ №
A11: Выдан | G11: На основании статьи 10 Федерального закона “О воинской обязанности и военной службе” и статьи 50 Положения о воинском учете, утвержденного Постановлением Правительства Российской Федерации от 27 ноября 2006 г. № 719, Вам НАДЛЕЖИТ ВСТАТЬ НА ВОИНСКИЙ УЧЕТ в военном комиссариате (органе местного самоуправления)
A12: =Карточка!A48 -> <Орган, выдавший документ, удостоверяющего личность>
A14: Дата выдачи | C14: =Карточка!J46 -> <Дата выдачи документа, удостоверяющего личность> г.
A16: Код подразделения | C16: =Карточка!L48 -> <Код подразделения>
A18: Направлен в военный комиссариат (орган местного самоуправления) | G18: =Карточка!G95 -> <Военкомат>
A19: =Карточка!G95 -> <Военкомат> | G19: по адресу: | H19: =Сведения!G6 -> <Адрес военкомата>
A22: Регистрируется по месту жительства (учитывается по месту пребывания) | G22: В соответствии с законодательством Российской Федерации при уклонении граждан от постановки на воинский учет органы внутренних дел обязаны произвести их розыск и задержание, а военный комиссариат - привлечь их к ответственности
A24: =Карточка!D56 -> <Адрес места проживания>
A25: Направление вручено гражданину
A26: "____" ________________ 20____ г.
G27: (наименование подразделения территориального органа ФМС России)
A28: Расписка гражданина в получении направления для постановки на воинский учет | G28: Подпись
H29: (фамилия и должность лица, выдавшего
G31: направление для постановки на воинский учет)
A32: "____" ________________ 20____ г.
G33: М.П.
G34: "____" ________________ 20 ____ г.
G35: Примечания: 1. Распорядок работы военного комиссариата: в рабочие дни с____ до____ , обед с____до____приемные дни, неприемные дни. Прием на воинский учет осуществляется: военнообязанных – офицеров запаса – каб. №____ ; прапорщиков (мичманов), сержантов (старшин), солдат (матросов) запаса – каб. №___ ; призывников – каб. №____ . 2. Для постановки на воинский учет при себе иметь: паспорт, военный билет (временное удостоверение, выданное взамен военного билета) или удостоверение гражданина, подлежащего призыву на военную службу, водительское удостоверение (для граждан, проходивших военную службу на воинских должностях водителей и (или) работающих водителями), настоящее направление.
A44: Отметка (мастичный штамп) о постановке на воинский учет в военном комиссариате (органе местного самоуправления) | F44: Л И Н И Я О Т Р Е З А
A52: "____" ________________ 20____ г.
A54: Выписка из Кодекса Российской Федерации об административных правонарушениях: “Статья 21.5. Неисполнение гражданами обязанностей по воинскому учету: 1. Неявка гражданина без уважительной причины в указанные в повестке военного комиссариата время и место либо по вызову иного органа, осуществляющего воинский учет, - влечет наложение административного штрафа в размере от десяти тысяч до тридцати тысяч рублей. 2. Несообщение гражданином в установленном федеральным законом порядке в военный комиссариат или орган, осуществляющий первичный воинский учет, об изменении семейного положения, образования, места работы (учебы) или должности, сведений о переезде на новое место пребывания, не подтвержденное регистрацией, - влечет наложение административного штрафа в размере от одной тысячи до пяти тысяч рублей. 3. Несообщение гражданином в установленном федеральным законом порядке в военный комиссариат или орган, осуществляющий первичный воинский учет, сведений о выезде из Российской Федерации на срок более шести месяцев или въезде в Российскую Федерацию либо неявка в военный комиссариат в установленный федеральным законом срок в случае наступления указанных событий - влечет наложение административного штрафа в размере от пяти тысяч до пятнадцати тысяч рублей. 4. Несообщение в установленном федеральным законом порядке в военный комиссариат или орган, осуществляющий первичный воинский учет, гражданином, подлежащим призыву на военную службу, о выезде в период проведения призыва на срок более трех месяцев с места жительства или места пребывания, в том числе не подтвержденных регистрацией по месту жительства и (или) месту пребывания, - влечет наложение административного штрафа в размере от десяти тысяч до двадцати тысяч рублей.

Sheet Письмо 13
A1: =Карточка!A8 -> <Полное наименование>
A2: =Сведения!A1 -> <Краткое наименование>
A3: =Сведения!D30 -> <Юридический адрес>
C4: ИНН | D4: =Сведения!B2 -> <ИНН организации>/<КПП организации> | G4: =Сведения!A3 -> ОГРН(-ИП) <ОГРН организации>
F6: Военному комиссару (руководителю)
F7: =Карточка!G95 -> <Военкомат>
F8: =Сведения!G6 -> <Адрес военкомата>
A11: Информационное письмо
A13: "___" ________ 20 ___ г.
A15: Настоящим сообщаем, что в соответствии с п. 30 постановления Правительства РФ от 27.11.2006 № 719 при проведении учетной работы был выявлен факт отсутствия отметки на стр. 13 паспорта гражданина
A16: =Карточка!D15 -> <Фамилия> | E16: =Карточка!D17 -> <Имя> | I16: =Карточка!D19 -> <Отчество> | M16: .
A17: =Карточка!D15 -> <Фамилия> | D17: =Карточка!D17 -> <Имя> | G17: =Карточка!D19 -> <Отчество> | K17: , работает в
A18: =Карточка!A8 -> <Полное наименование> | M18: ,
A19: с | B19: =Карточка!B95 -> <Дата приказа о приеме> | D19: , приказ | F19: =Карточка!B95 -> <Дата приказа о приеме> | H19: =Карточка!A95 -> <Приказ №> | J19: .
B20: =Карточка!L102 -> <Фамилия> | D20: =Карточка!K102 -> <Инициалы имени, отчества> | E20: направляется для проставления в его (её) паспорте
A21: отметки об отношении к воинской службе в соответствии с требованием п. 32 Методических рекомендаций по ведению воинского учета в организациях, утвержденных Генштабом Вооруженных Сил РФ 11.07.2017.
B25: Паспорт | C25: =B20 -> <Фамилия> | F25: =D20 -> <Инициалы имени, отчества> | G25: серия | H25: =Карточка!D46 -> <Серия документа, удостоверяющего личность> | I25: № | J25: =Карточка!F46 -> <Номер документа, удостоверяющего личность> | L25: ,выдан
A26: =Карточка!A48 -> <Орган, выдавший документ, удостоверяющего личность> | M26: ,
A27: код подразделения | D27: =Карточка!L48 -> <Код подразделения> | F27: =Карточка!I77 -> <Документ воинского учёта> | I27: =Карточка!K77 -> <Серия документа воинского учёта> | J27: =Карточка!L77 -> <Номер документа воинского учёта> | L27: выдан | M27: ,
A28: =Карточка!I79 -> <Отдел, выдавший документ воинского учёта> | M28: ,
A29: =Карточка!I81 -> <Дата выдачи документа воинского учёта> г. | C29: .
A32: Руководитель организации
A33: =Сведения!A38 -> <Должность руководителя> | J33: =Сведения!M38 -> <Инициалы имени, отчества руководителя> <Фамилия руководителя>
G34: подпись
A35: М.П. (при наличии)

Sheet Лист6
A1: =Карточка!A8 -> <Полное наименование>
A2: =Сведения!A1 -> <Краткое наименование>
A3: =Сведения!D30 -> <Юридический адрес>
C4: ИНН | D4: =Сведения!B2 -> <ИНН организации>/<КПП организации> | G4: =Сведения!A3 -> ОГРН(-ИП) <ОГРН организации>
F6: Военному комиссару (руководителю)
F7: =Карточка!G95 -> <Военкомат>
F8: =Сведения!G6 -> <Адрес военкомата>
A11: Информационное письмо
A13: "____" ____________ 20 ___ г.
A15: Настоящим сообщаем, что в соответствии с п. 30 постановления Правительства РФ от 27.11.2006 № 719 при проведении учетной работы был выявлен факт отсутствия отметки на стр. 13 паспорта гражданина
A16: =Карточка!D15 -> <Фамилия> | E16: =Карточка!D17 -> <Имя> | I16: =Карточка!D19 -> <Отчество> | M16: .
A17: =Карточка!D15 -> <Фамилия> | D17: =Карточка!D17 -> <Имя> | G17: =Карточка!D19 -> <Отчество> | K17: , работает в
A18: =Карточка!A8 -> <Полное наименование> | M18: ,
A19: с | B19: =Карточка!B95 -> <Дата приказа о приеме> | D19: , приказ | F19: =Карточка!B95 -> <Дата приказа о приеме> | H19: =Карточка!A95 -> <Приказ №> | J19: .
B20: =Карточка!L102 -> <Фамилия> | D20: =Карточка!K102 -> <Инициалы имени, отчества> | E20: направляется для проставления в его (её) паспорте
A21: отметки об отношении к воинской службе в соответствии с требованием п. 32 Методических рекомендаций по ведению воинского учета в организациях, утвержденных Генштабом Вооруженных Сил РФ 11.07.2017.
B25: Паспорт | C25: =Карточка!L102 -> <Фамилия> | F25: =Карточка!K102 -> <Инициалы имени, отчества> | G25: серия | H25: =Карточка!D46 -> <Серия документа, удостоверяющего личность> | I25: № | J25: =Карточка!F46 -> <Номер документа, удостоверяющего личность> | L25: ,выдан
A26: =Карточка!A48 -> <Орган, выдавший документ, удостоверяющего личность> | M26: ,
A27: код подразделения | D27: =Карточка!L48 -> <Код подразделения> | F27: <Документ воинского учёта> | I27: =Карточка!K77 -> <Серия документа воинского учёта> | J27: =Карточка!L77 -> <Номер документа воинского учёта> | L27: выдан | M27: ,
A28: =Карточка!I79 -> <Отдел, выдавший документ воинского учёта> | M28: ,
A29: =Карточка!I81 -> <Дата выдачи документа воинского учёта> г. | C29: .
A32: Руководитель организации
A33: =Сведения!A38 -> <Должность руководителя> | J33: =Сведения!M38 -> <Инициалы имени, отчества руководителя> <Фамилия руководителя>
G34: подпись
A35: М.П. (при наличии)

Sheet Сведения об изменениях
P1: Приложение № 2 к Порядку (п. 2)
C2: =Сведения!A1 -> <Краткое наименование> | M2: Военному комиссару
C3: ИНН/КПП | E3: =Сведения!B2 -> <ИНН организации>/<КПП организации> | M3: =Карточка!G95 -> <Военкомат>
C4: =Сведения!A3 -> ОГРН(-ИП) <ОГРН организации>
M5: =Сведения!G6 -> <Адрес военкомата>
A7: СВЕДЕНИЯ об изменениях семейного положения, образования, структурного подразделения организации, должности, места жительства или места пребывания, состояния здоровья граждан, состоящих на воинском учете
A8: =Карточка!A8 -> <Полное наименование>
F9: (наименование организации)
A11: Адрес организации | G11: =Сведения!D31 -> <Фактический адрес>
A12: Ответственный за военно-учетную работу | J12: =Карточка!D100 -> <Должность ответственного за ВУ> | O12: =Сверка!P14 -> 8-926-641-37-58 | S12: =Карточка!K100 -> <Инициалы имени, отчества ответственного за ВУ> <Фамилия ответственного за ВУ>
I13: (должность) | S13: (инициал имени, фамилия)
A14: № п/п | B14: Фамилия, имя, отчество (при наличии) | E14: Воинское звание | J14: Год рождения | M14: Состоит на воинском учете: общий (номер команды, партии), специальный | P14: Содержание изменений | U14: Примечание
A15: 1 | B15: 2 | E15: 3 | J15: 4 | M15: 5 | P15: 6 | U15: 7
A16: 1 | B16: =Карточка!D15 -> <Фамилия> | E16: =Карточка!D67 -> <Воинское звание> | J16: =Карточка!D21 -> <Дата рождения> | M16: =Сверка!N18 -> общий | U16: =S18 -> 0
B17: =Карточка!D17 -> <Имя> | R17: =Карточка!C97 -> 0
B18: =Карточка!D19 -> <Отчество> | Q18: =Карточка!A97 -> 0 | S18: =Карточка!B97 -> 0
A34: Руководитель организации | R34: =Сведения!M38 -> <Инициалы имени, отчества руководителя> <Фамилия руководителя>
H35: (подпись, инициал имени, фамилия)
